{"url":"https://api.github.com/repos/willmcgugan/rich/issues/455","repository_url":"https://api.github.com/repos/willmcgugan/rich","labels_url":"https://api.github.com/repos/willmcgugan/rich/issues/455/labels{/name}","comments_url":"https://api.github.com/repos/willmcgugan/rich/issues/455/comments","events_url":"https://api.github.com/repos/willmcgugan/rich/issues/455/events","html_url":"https://github.com/willmcgugan/rich/pull/455","id":753031839,"node_id":"MDExOlB1bGxSZXF1ZXN0NTI5MTkxMTU5","number":455,"title":"Use the proper error message with caused exceptions","user":{"login":"nneonneo","id":75449,"node_id":"MDQ6VXNlcjc1NDQ5","avatar_url":"https://avatars3.githubusercontent.com/u/75449?v=4","gravatar_id":"","url":"https://api.github.com/users/nneonneo","html_url":"https://github.com/nneonneo","followers_url":"https://api.github.com/users/nneonneo/followers","following_url":"https://api.github.com/users/nneonneo/following{/other_user}","gists_url":"https://api.github.com/users/nneonneo/gists{/gist_id}","starred_url":"https://api.github.com/users/nneonneo/starred{/owner}{/repo}","subscriptions_url":"https://api.github.com/users/nneonneo/subscriptions","organizations_url":"https://api.github.com/users/nneonneo/orgs","repos_url":"https://api.github.com/users/nneonneo/repos","events_url":"https://api.github.com/users/nneonneo/events{/privacy}","received_events_url":"https://api.github.com/users/nneonneo/received_events","type":"User","site_admin":false},"labels":[],"state":"closed","locked":false,"assignee":null,"assignees":[],"milestone":null,"comments":2,"created_at":"2020-11-29T22:25:43Z","updated_at":"2020-12-11T15:23:45Z","closed_at":"2020-12-11T15:23:45Z","author_association":"CONTRIBUTOR","active_lock_reason":null,"pull_request":{"url":"https://api.github.com/repos/willmcgugan/rich/pulls/455","html_url":"https://github.com/willmcgugan/rich/pull/455","diff_url":"https://github.com/willmcgugan/rich/pull/455.diff","patch_url":"https://github.com/willmcgugan/rich/pull/455.patch"},"body":"## Type of changes\r\n\r\n- [x] Bug fix\r\n- [ ] New feature\r\n- [ ] Documentation / docstrings\r\n- [x] Tests\r\n- [ ] Other\r\n\r\n## Checklist\r\n\r\n- [x] I've run the latest [black](https://github.com/psf/black) with default args on new code.\r\n- [x] I've updated CHANGELOG.md and CONTRIBUTORS.md where appropriate.\r\n- [x] I've added tests for new code.\r\n- [x] I accept that @willmcgugan may be pedantic in the code review.\r\n\r\n## Description\r\n\r\nWhen an exception is raised using \"from\", the chained exception goes into\r\n__cause__, which results in a different message using Python's native traceback\r\nhandler. This patch properly replicates that error message.\r\n","closed_by":{"login":"willmcgugan","id":554369,"node_id":"MDQ6VXNlcjU1NDM2OQ==","avatar_url":"https://avatars3.githubusercontent.com/u/554369?v=4","gravatar_id":"","url":"https://api.github.com/users/willmcgugan","html_url":"https://github.com/willmcgugan","followers_url":"https://api.github.com/users/willmcgugan/followers","following_url":"https://api.github.com/users/willmcgugan/following{/other_user}","gists_url":"https://api.github.com/users/willmcgugan/gists{/gist_id}","starred_url":"https://api.github.com/users/willmcgugan/starred{/owner}{/repo}","subscriptions_url":"https://api.github.com/users/willmcgugan/subscriptions","organizations_url":"https://api.github.com/users/willmcgugan/orgs","repos_url":"https://api.github.com/users/willmcgugan/repos","events_url":"https://api.github.com/users/willmcgugan/events{/privacy}","received_events_url":"https://api.github.com/users/willmcgugan/received_events","type":"User","site_admin":false},"performed_via_github_app":null}